Workbook

Sheet Instructions
B2: NDPA 2023 / GAID 2025 Compliance Audit Work Plan
B3: Typical Nigerian University — prepared to support the annual Compliance Audit Returns (CAR) under GAID Article 10
B5: Purpose | C5: Risk-based audit work plan covering every faculty, school, directorate and central department so the University can evidence compliance and file its CAR (Schedule 2 template) through a licensed DPCO.
B6: Audit period | C6: 1 January – 31 December 2026 (audit year). Fieldwork Nov 2026 – Feb 2027. CAR filing deadline: 31 March 2027 (GAID Art. 10(7)).
B7: Assumption | C7: The University is a Data Controller of Major Importance (likely EHL as a public institution). Confirm the actual level against Schedule 7 — only UHL/EHL file CAR; OHL renews registration instead (Art. 9(2)-(3)).
B8: Structure | C8: Dashboard = audit universe + live scores. CAR Framework = base controls applied to every unit. Timeline = audit phases. One tab per unit, prefixed CEN / DIR / DEPT / FAC / SCH.
B9: Academic departments | C9: Academic departments (e.g., Dept. of Economics) sit inside their faculty tab — the faculty audit samples records at department level. Add a tab per academic department by copying a faculty tab if needed.
B10: Cells to edit | C10: Yellow cells only: unit header details (Head of Unit, Lead Auditor, planned dates), Risk, Auditor, Status, Compliance Rating, Findings, Recommendation, Management Response, Target Date. Blue-header columns are reference content. Grey cells are formulas — do not overwrite.
B11: Scoring | C11: Compliant = 100%, Partially Compliant = 50%, Non-Compliant = 0%, Not Applicable = excluded. Unit score = average of rated controls; it flows to the Dashboard automatically.
B12: Planned dates | C12: Each control row inherits the unit's planned start/end from the header. Change the header dates and all rows update; overwrite a row date only if that control is scheduled separately.
B13: Source | C13: Nigeria Data Protection Commission, NDP Act General Application and Implementation Directive (GAID) 2025, NDPC/NDP ACT-GAID/01/2025, issued 20 March 2025, effective 19 September 2025 — ndpc.gov.ng. Unit profiles are typical assumptions; adjust to the actual institution.
B15: Legend
C16: Input cell — fill in during the audit
C17: Formula cell — calculated automatically
C18: Reference / plan content
B20: Example of a completed control row
B21: Ref | C21: DEPT-ADM-04
B22: CAR Area | C22: Consent (CAR disclosure)
B23: Risk | C23: High
B24: Auditor | C24: A. Bello
B25: Status | C25: Completed
B26: Compliance Rating | C26: Partially Compliant
B27: Findings | C27: Admissions portal captures DOB but has no parental consent step for applicants under 18; 212 applicants aged 16–17 in 2026 cycle.
B28: Recommendation | C28: Add guardian consent screen for under-18 applicants; retro-notify guardians of current minors.
B29: Management Response | C29: Agreed. Owner: Admissions Officer with DICT. Target: 30 April 2027.

Sheet Dashboard
A1: Audit Universe & Compliance Dashboard
A2: Typical Nigerian University — NDPA 2023 / GAID 2025 Art. 10 CAR audit (2026 audit year, filing by 31 March 2027). Scores update from each unit tab.
A4: Summary by Unit Type
A5: Unit Type | B5: No. of Units | C5: Controls | D5: Completed | E5: Non-Compliant | F5: Avg. Score
A6: Central Governance | B6: =COUNTIF($C$14:$C$51,A6) -> 1 | C6: =SUMIF($C$14:$C$51,A6,$H$14:$H$51) -> 39 | D6: =SUMIF($C$14:$C$51,A6,$I$14:$I$51) -> 0 | E6: =SUMIF($C$14:$C$51,A6,$L$14:$L$51) -> 0 | F6: =_xlfn.IFERROR(_xlfn.AVERAGEIF($C$14:$C$51,A6,$M$14:$M$51),"")
A7: Directorate | B7: =COUNTIF($C$14:$C$51,A7) -> 10 | C7: =SUMIF($C$14:$C$51,A7,$H$14:$H$51) -> 248 | D7: =SUMIF($C$14:$C$51,A7,$I$14:$I$51) -> 0 | E7: =SUMIF($C$14:$C$51,A7,$L$14:$L$51) -> 0 | F7: =_xlfn.IFERROR(_xlfn.AVERAGEIF($C$14:$C$51,A7,$M$14:$M$51),"")
A8: Department | B8: =COUNTIF($C$14:$C$51,A8) -> 9 | C8: =SUMIF($C$14:$C$51,A8,$H$14:$H$51) -> 218 | D8: =SUMIF($C$14:$C$51,A8,$I$14:$I$51) -> 0 | E8: =SUMIF($C$14:$C$51,A8,$L$14:$L$51) -> 0 | F8: =_xlfn.IFERROR(_xlfn.AVERAGEIF($C$14:$C$51,A8,$M$14:$M$51),"")
A9: Faculty | B9: =COUNTIF($C$14:$C$51,A9) -> 13 | C9: =SUMIF($C$14:$C$51,A9,$H$14:$H$51) -> 306 | D9: =SUMIF($C$14:$C$51,A9,$I$14:$I$51) -> 0 | E9: =SUMIF($C$14:$C$51,A9,$L$14:$L$51) -> 0 | F9: =_xlfn.IFERROR(_xlfn.AVERAGEIF($C$14:$C$51,A9,$M$14:$M$51),"")
A10: School | B10: =COUNTIF($C$14:$C$51,A10) -> 5 | C10: =SUMIF($C$14:$C$51,A10,$H$14:$H$51) -> 122 | D10: =SUMIF($C$14:$C$51,A10,$I$14:$I$51) -> 0 | E10: =SUMIF($C$14:$C$51,A10,$L$14:$L$51) -> 0 | F10: =_xlfn.IFERROR(_xlfn.AVERAGEIF($C$14:$C$51,A10,$M$14:$M$51),"")
A11: University Total | B11: =SUM(B6:B10) -> 38 | C11: =SUM(C6:C10) -> 933 | D11: =SUM(D6:D10) -> 0 | E11: =SUM(E6:E10) -> 0 | F11: =_xlfn.IFERROR(AVERAGE($M$14:$M$51),"")
A12: Audit Universe
A13: # | B13: Unit | C13: Unit Type | D13: Reports To | E13: Head of Unit | F13: Inherent Risk | G13: Planned Start | H13: Controls | I13: Completed | J13: Compliant | K13: Partial | L13: Non-Compliant | M13: Score | N13: Open Tab
A14: 1 | B14: Data Protection Office (DPO) & Central Governance | C14: Central Governance | D14: Vice-Chancellor / University Management | E14: ='CEN-DPO Office'!C7 -> [Enter name] | F14: ='CEN-DPO Office'!C11 -> High | G14: ='CEN-DPO Office'!K5 -> 46328 | H14: ='CEN-DPO Office'!K7 -> 39 | I14: ='CEN-DPO Office'!K8 -> 0 | J14: ='CEN-DPO Office'!K9 -> 0 | K14: ='CEN-DPO Office'!K10 -> 0 | L14: ='CEN-DPO Office'!K11 -> 0 | M14: ='CEN-DPO Office'!K13 | N14: Open →
A15: 2 | B15: Directorate of Information & Communication Technology (DICT) | C15: Directorate | D15: Vice-Chancellor | E15: ='DIR-ICT'!C7 -> [Enter name] | F15: ='DIR-ICT'!C11 -> High | G15: ='DIR-ICT'!K5 -> 46342 | H15: ='DIR-ICT'!K7 -> 28 | I15: ='DIR-ICT'!K8 -> 0 | J15: ='DIR-ICT'!K9 -> 0 | K15: ='DIR-ICT'!K10 -> 0 | L15: ='DIR-ICT'!K11 -> 0 | M15: ='DIR-ICT'!K13 | N15: Open →
A16: 3 | B16: Directorate of Academic Planning | C16: Directorate | D16: Vice-Chancellor | E16: ='DIR-Academic Planning'!C7 -> [Enter name] | F16: ='DIR-Academic Planning'!C11 -> Medium | G16: ='DIR-Academic Planning'!K5 -> 46342 | H16: ='DIR-Academic Planning'!K7 -> 24 | I16: ='DIR-Academic Planning'!K8 -> 0 | J16: ='DIR-Academic Planning'!K9 -> 0 | K16: ='DIR-Academic Planning'!K10 -> 0 | L16: ='DIR-Academic Planning'!K11 -> 0 | M16: ='DIR-Academic Planning'!K13 | N16: Open →
A17: 4 | B17: Directorate of Quality Assurance | C17: Directorate | D17: Vice-Chancellor | E17: ='DIR-Quality Assurance'!C7 -> [Enter name] | F17: ='DIR-Quality Assurance'!C11 -> Medium | G17: ='DIR-Quality Assurance'!K5 -> 46342 | H17: ='DIR-Quality Assurance'!K7 -> 24 | I17: ='DIR-Quality Assurance'!K8 -> 0 | J17: ='DIR-Quality Assurance'!K9 -> 0 | K17: ='DIR-Quality Assurance'!K10 -> 0 | L17: ='DIR-Quality Assurance'!K11 -> 0 | M17: ='DIR-Quality Assurance'!K13 | N17: Open →
A18: 5 | B18: Directorate of Physical Planning & Works | C18: Directorate | D18: Vice-Chancellor | E18: ='DIR-Physical Planning'!C7 -> [Enter name] | F18: ='DIR-Physical Planning'!C11 -> Low | G18: ='DIR-Physical Planning'!K5 -> 46342 | H18: ='DIR-Physical Planning'!K7 -> 23 | I18: ='DIR-Physical Planning'!K8 -> 0 | J18: ='DIR-Physical Planning'!K9 -> 0 | K18: ='DIR-Physical Planning'!K10 -> 0 | L18: ='DIR-Physical Planning'!K11 -> 0 | M18: ='DIR-Physical Planning'!K13 | N18: Open →
A19: 6 | B19: Directorate of Health Services (University Health Centre) | C19: Directorate | D19: Vice-Chancellor | E19: ='DIR-Health Services'!C7 -> [Enter name] | F19: ='DIR-Health Services'!C11 -> High | G19: ='DIR-Health Services'!K5 -> 46342 | H19: ='DIR-Health Services'!K7 -> 26 | I19: ='DIR-Health Services'!K8 -> 0 | J19: ='DIR-Health Services'!K9 -> 0 | K19: ='DIR-Health Services'!K10 -> 0 | L19: ='DIR-Health Services'!K11 -> 0 | M19: ='DIR-Health Services'!K13 | N19: Open →
A20: 7 | B20: Directorate of Security Services | C20: Directorate | D20: Vice-Chancellor | E20: ='DIR-Security Services'!C7 -> [Enter name] | F20: ='DIR-Security Services'!C11 -> High | G20: ='DIR-Security Services'!K5 -> 46342 | H20: ='DIR-Security Services'!K7 -> 26 | I20: ='DIR-Security Services'!K8 -> 0 | J20: ='DIR-Security Services'!K9 -> 0 | K20: ='DIR-Security Services'!K10 -> 0 | L20: ='DIR-Security Services'!K11 -> 0 | M20: ='DIR-Security Services'!K13 | N20: Open →
A21: 8 | B21: Directorate of Research, Innovation & Development | C21: Directorate | D21: DVC (Research) | E21: ='DIR-Research & Dev'!C7 -> [Enter name] | F21: ='DIR-Research & Dev'!C11 -> Medium | G21: ='DIR-Research & Dev'!K5 -> 46342 | H21: ='DIR-Research & Dev'!K7 -> 24 | I21: ='DIR-Research & Dev'!K8 -> 0 | J21: ='DIR-Research & Dev'!K9 -> 0 | K21: ='DIR-Research & Dev'!K10 -> 0 | L21: ='DIR-Research & Dev'!K11 -> 0 | M21: ='DIR-Research & Dev'!K13 | N21: Open →
A22: 9 | B22: Directorate of Linkages & International Collaborations | C22: Directorate | D22: Vice-Chancellor | E22: ='DIR-Linkages'!C7 -> [Enter name] | F22: ='DIR-Linkages'!C11 -> High | G22: ='DIR-Linkages'!K5 -> 46342 | H22: ='DIR-Linkages'!K7 -> 24 | I22: ='DIR-Linkages'!K8 -> 0 | J22: ='DIR-Linkages'!K9 -> 0 | K22: ='DIR-Linkages'!K10 -> 0 | L22: ='DIR-Linkages'!K11 -> 0 | M22: ='DIR-Linkages'!K13 | N22: Open →
A23: 10 | B23: Directorate of Student Affairs | C23: Directorate | D23: DVC (Academic) | E23: ='DIR-Student Affairs'!C7 -> [Enter name] | F23: ='DIR-Student Affairs'!C11 -> High | G23: ='DIR-Student Affairs'!K5 -> 46342 | H23: ='DIR-Student Affairs'!K7 -> 25 | I23: ='DIR-Student Affairs'!K8 -> 0 | J23: ='DIR-Student Affairs'!K9 -> 0 | K23: ='DIR-Student Affairs'!K10 -> 0 | L23: ='DIR-Student Affairs'!K11 -> 0 | M23: ='DIR-Student Affairs'!K13 | N23: Open →
A24: 11 | B24: Directorate of Advancement, Alumni & Endowment | C24: Directorate | D24: Vice-Chancellor | E24: ='DIR-Advancement'!C7 -> [Enter name] | F24: ='DIR-Advancement'!C11 -> Medium | G24: ='DIR-Advancement'!K5 -> 46342 | H24: ='DIR-Advancement'!K7 -> 24 | I24: ='DIR-Advancement'!K8 -> 0 | J24: ='DIR-Advancement'!K9 -> 0 | K24: ='DIR-Advancement'!K10 -> 0 | L24: ='DIR-Advancement'!K11 -> 0 | M24: ='DIR-Advancement'!K13 | N24: Open →
A25: 12 | B25: Registry – Establishments / Human Resources | C25: Department | D25: Registrar | E25: ='DEPT-HR Establishments'!C7 -> [Enter name] | F25: ='DEPT-HR Establishments'!C11 -> High | G25: ='DEPT-HR Establishments'!K5 -> 46391 | H25: ='DEPT-HR Establishments'!K7 -> 25 | I25: ='DEPT-HR Establishments'!K8 -> 0 | J25: ='DEPT-HR Establishments'!K9 -> 0 | K25: ='DEPT-HR Establishments'!K10 -> 0 | L25: ='DEPT-HR Establishments'!K11 -> 0 | M25: ='DEPT-HR Establishments'!K13 | N25: Open →
A26: 13 | B26: Registry – Admissions Office | C26: Department | D26: Registrar | E26: ='DEPT-Admissions'!C7 -> [Enter name] | F26: ='DEPT-Admissions'!C11 -> High | G26: ='DEPT-Admissions'!K5 -> 46391 | H26: ='DEPT-Admissions'!K7 -> 26 | I26: ='DEPT-Admissions'!K8 -> 0 | J26: ='DEPT-Admissions'!K9 -> 0 | K26: ='DEPT-Admissions'!K10 -> 0 | L26: ='DEPT-Admissions'!K11 -> 0 | M26: ='DEPT-Admissions'!K13 | N26: Open →
A27: 14 | B27: Registry – Examinations & Records | C27: Department | D27: Registrar | E27: ='DEPT-Exams & Records'!C7 -> [Enter name] | F27: ='DEPT-Exams & Records'!C11 -> High | G27: ='DEPT-Exams & Records'!K5 -> 46391 | H27: ='DEPT-Exams & Records'!K7 -> 24 | I27: ='DEPT-Exams & Records'!K8 -> 0 | J27: ='DEPT-Exams & Records'!K9 -> 0 | K27: ='DEPT-Exams & Records'!K10 -> 0 | L27: ='DEPT-Exams & Records'!K11 -> 0 | M27: ='DEPT-Exams & Records'!K13 | N27: Open →
A28: 15 | B28: Registry – Council & Senate Affairs | C28: Department | D28: Registrar | E28: ='DEPT-Council & Senate'!C7 -> [Enter name] | F28: ='DEPT-Council & Senate'!C11 -> Medium | G28: ='DEPT-Council & Senate'!K5 -> 46391 | H28: ='DEPT-Council & Senate'!K7 -> 23 | I28: ='DEPT-Council & Senate'!K8 -> 0 | J28: ='DEPT-Council & Senate'!K9 -> 0 | K28: ='DEPT-Council & Senate'!K10 -> 0 | L28: ='DEPT-Council & Senate'!K11 -> 0 | M28: ='DEPT-Council & Senate'!K13 | N28: Open →
A29: 16 | B29: Bursary Department | C29: Department | D29: Vice-Chancellor | E29: ='DEPT-Bursary'!C7 -> [Enter name] | F29: ='DEPT-Bursary'!C11 -> High | G29: ='DEPT-Bursary'!K5 -> 46391 | H29: ='DEPT-Bursary'!K7 -> 24 | I29: ='DEPT-Bursary'!K8 -> 0 | J29: ='DEPT-Bursary'!K9 -> 0 | K29: ='DEPT-Bursary'!K10 -> 0 | L29: ='DEPT-Bursary'!K11 -> 0 | M29: ='DEPT-Bursary'!K13 | N29: Open →
A30: 17 | B30: University Library | C30: Department | D30: Vice-Chancellor | E30: ='DEPT-Library'!C7 -> [Enter name] | F30: ='DEPT-Library'!C11 -> Medium | G30: ='DEPT-Library'!K5 -> 46391 | H30: ='DEPT-Library'!K7 -> 24 | I30: ='DEPT-Library'!K8 -> 0 | J30: ='DEPT-Library'!K9 -> 0 | K30: ='DEPT-Library'!K10 -> 0 | L30: ='DEPT-Library'!K11 -> 0 | M30: ='DEPT-Library'!K13 | N30: Open →
A31: 18 | B31: Legal Unit | C31: Department | D31: Registrar | E31: ='DEPT-Legal Unit'!C7 -> [Enter name] | F31: ='DEPT-Legal Unit'!C11 -> Medium | G31: ='DEPT-Legal Unit'!K5 -> 46391 | H31: ='DEPT-Legal Unit'!K7 -> 25 | I31: ='DEPT-Legal Unit'!K8 -> 0 | J31: ='DEPT-Legal Unit'!K9 -> 0 | K31: ='DEPT-Legal Unit'!K10 -> 0 | L31: ='DEPT-Legal Unit'!K11 -> 0 | M31: ='DEPT-Legal Unit'!K13 | N31: Open →
A32: 19 | B32: Information, Public Relations & Protocol | C32: Department | D32: Vice-Chancellor | E32: ='DEPT-Info & PR'!C7 -> [Enter name] | F32: ='DEPT-Info & PR'!C11 -> Medium | G32: ='DEPT-Info & PR'!K5 -> 46391 | H32: ='DEPT-Info & PR'!K7 -> 24 | I32: ='DEPT-Info & PR'!K8 -> 0 | J32: ='DEPT-Info & PR'!K9 -> 0 | K32: ='DEPT-Info & PR'!K10 -> 0 | L32: ='DEPT-Info & PR'!K11 -> 0 | M32: ='DEPT-Info & PR'!K13 | N32: Open →
A33: 20 | B33: Procurement Department | C33: Department | D33: Vice-Chancellor | E33: ='DEPT-Procurement'!C7 -> [Enter name] | F33: ='DEPT-Procurement'!C11 -> Medium | G33: ='DEPT-Procurement'!K5 -> 46391 | H33: ='DEPT-Procurement'!K7 -> 23 | I33: ='DEPT-Procurement'!K8 -> 0 | J33: ='DEPT-Procurement'!K9 -> 0 | K33: ='DEPT-Procurement'!K10 -> 0 | L33: ='DEPT-Procurement'!K11 -> 0 | M33: ='DEPT-Procurement'!K13 | N33: Open →
A34: 21 | B34: Faculty of Arts | C34: Faculty | D34: DVC (Academic) | E34: ='FAC-Arts'!C7 -> [Enter name] | F34: ='FAC-Arts'!C11 -> Medium | G34: ='FAC-Arts'!K5 -> 46412 | H34: ='FAC-Arts'!K7 -> 23 | I34: ='FAC-Arts'!K8 -> 0 | J34: ='FAC-Arts'!K9 -> 0 | K34: ='FAC-Arts'!K10 -> 0 | L34: ='FAC-Arts'!K11 -> 0 | M34: ='FAC-Arts'!K13 | N34: Open →
A35: 22 | B35: Faculty of Education | C35: Faculty | D35: DVC (Academic) | E35: ='FAC-Education'!C7 -> [Enter name] | F35: ='FAC-Education'!C11 -> High | G35: ='FAC-Education'!K5 -> 46412 | H35: ='FAC-Education'!K7 -> 24 | I35: ='FAC-Education'!K8 -> 0 | J35: ='FAC-Education'!K9 -> 0 | K35: ='FAC-Education'!K10 -> 0 | L35: ='FAC-Education'!K11 -> 0 | M35: ='FAC-Education'!K13 | N35: Open →
A36: 23 | B36: Faculty of Engineering | C36: Faculty | D36: DVC (Academic) | E36: ='FAC-Engineering'!C7 -> [Enter name] | F36: ='FAC-Engineering'!C11 -> Medium | G36: ='FAC-Engineering'!K5 -> 46412 | H36: ='FAC-Engineering'!K7 -> 23 | I36: ='FAC-Engineering'!K8 -> 0 | J36: ='FAC-Engineering'!K9 -> 0 | K36: ='FAC-Engineering'!K10 -> 0 | L36: ='FAC-Engineering'!K11 -> 0 | M36: ='FAC-Engineering'!K13 | N36: Open →
A37: 24 | B37: Faculty of Law | C37: Faculty | D37: DVC (Academic) | E37: ='FAC-Law'!C7 -> [Enter name] | F37: ='FAC-Law'!C11 -> High | G37: ='FAC-Law'!K5 -> 46412 | H37: ='FAC-Law'!K7 -> 24 | I37: ='FAC-Law'!K8 -> 0 | J37: ='FAC-Law'!K9 -> 0 | K37: ='FAC-Law'!K10 -> 0 | L37: ='FAC-Law'!K11 -> 0 | M37: ='FAC-Law'!K13 | N37: Open →
A38: 25 | B38: Faculty of Management Sciences | C38: Faculty | D38: DVC (Academic) | E38: ='FAC-Management Sciences'!C7 -> [Enter name] | F38: ='FAC-Management Sciences'!C11 -> Medium | G38: ='FAC-Management Sciences'!K5 -> 46412 | H38: ='FAC-Management Sciences'!K7 -> 23 | I38: ='FAC-Management Sciences'!K8 -> 0 | J38: ='FAC-Management Sciences'!K9 -> 0 | K38: ='FAC-Management Sciences'!K10 -> 0 | L38: ='FAC-Management Sciences'!K11 -> 0 | M38: ='FAC-Management Sciences'!K13 | N38: Open →
A39: 26 | B39: Faculty of Science | C39: Faculty | D39: DVC (Academic) | E39: ='FAC-Science'!C7 -> [Enter name] | F39: ='FAC-Science'!C11 -> Medium | G39: ='FAC-Science'!K5 -> 46412 | H39: ='FAC-Science'!K7 -> 23 | I39: ='FAC-Science'!K8 -> 0 | J39: ='FAC-Science'!K9 -> 0 | K39: ='FAC-Science'!K10 -> 0 | L39: ='FAC-Science'!K11 -> 0 | M39: ='FAC-Science'!K13 | N39: Open →
A40: 27 | B40: Faculty of Social Sciences | C40: Faculty | D40: DVC (Academic) | E40: ='FAC-Social Sciences'!C7 -> [Enter name] | F40: ='FAC-Social Sciences'!C11 -> High | G40: ='FAC-Social Sciences'!K5 -> 46412 | H40: ='FAC-Social Sciences'!K7 -> 24 | I40: ='FAC-Social Sciences'!K8 -> 0 | J40: ='FAC-Social Sciences'!K9 -> 0 | K40: ='FAC-Social Sciences'!K10 -> 0 | L40: ='FAC-Social Sciences'!K11 -> 0 | M40: ='FAC-Social Sciences'!K13 | N40: Open →
A41: 28 | B41: Faculty of Agriculture | C41: Faculty | D41: DVC (Academic) | E41: ='FAC-Agriculture'!C7 -> [Enter name] | F41: ='FAC-Agriculture'!C11 -> Low | G41: ='FAC-Agriculture'!K5 -> 46412 | H41: ='FAC-Agriculture'!K7 -> 23 | I41: ='FAC-Agriculture'!K8 -> 0 | J41: ='FAC-Agriculture'!K9 -> 0 | K41: ='FAC-Agriculture'!K10 -> 0 | L41: ='FAC-Agriculture'!K11 -> 0 | M41: ='FAC-Agriculture'!K13 | N41: Open →
...

Sheet CAR Framework
A1: CAR Base Control Framework (applied to every unit)
A2: Derived from GAID 2025 Art. 10 (Filing of CAR) and the obligations that feed the CAR (Arts. 7, 13, 15-19, 27-36, 45-49). Unit tabs add unit-specific controls after these.
A4: No. | B4: CAR Area | C4: GAID / NDPA Reference | D4: Control Objective | E4: Standard Audit Procedure | F4: Evidence | G4: Default Risk
A5: 1 | B5: ROPA | C5: GAID Art. 13(2)-(3), Art. 52; NDPA s.24(3) | D5: All processing activities of the unit are captured in the Record of Processing Activities (ROPA) submitted to the DPO. | E5: Walk through the unit's key processing (its key processes) and confirm each activity is captured in the ROPA with purpose, data categories, recipients and retention. | F5: Unit ROPA extract; process walkthrough notes | G5: High
A6: 2 | B6: Data inventory & sensitive data | C6: NDPA s.30; GAID Art. 28(3)(d) | D6: Personal and sensitive personal data held by the unit is identified and classified. | E6: Inventory data held (its data); flag sensitive categories and confirm they are recorded as such. | F6: Data inventory; classification register | G6: High
A7: 3 | B7: Lawful basis | C7: GAID Art. 16, 23; NDPA s.25 | D7: A documented lawful basis exists for each processing activity; legitimate interest supported by LIA. | E7: For each ROPA activity, confirm lawful basis is recorded and appropriate; where legitimate interest is used, inspect Schedule 8 LIA. | F7: Lawful basis register; LIAs | G7: High
A8: 4 | B8: Consent (CAR disclosure) | C8: GAID Art. 17, 18(1)-(2); NDPA s.26 | D8: Consent is obtained and recorded where required (marketing, sensitive data, children, incompatible further processing, transfers, automated decisions) — CAR must state reliance. | E8: Identify Art. 18(1) activities in the unit; test consent capture, records and ease of withdrawal for a sample of 5. | F8: Consent forms/records; withdrawal mechanism | G8: High
A9: 5 | B9: Privacy notice at collection | C9: GAID Art. 27; Art. 7(j)-(m); NDPA s.27 | D9: Data subjects receive clear privacy information at every collection point (forms, portals, surveys). | E9: Collect all forms/portals used by the unit; check each notice against Art. 27(3)(a)-(j). | F9: Forms; screenshots; notice checklist | G9: Medium
A10: 6 | B10: Minimisation & purpose limitation | C10: GAID Art. 15 & Sch. 1; NDPA s.24(1)(b),(c) | D10: Only data necessary for the stated purpose is collected and used. | E10: Review fields on the unit forms and systems (its systems); identify excessive fields (e.g., religion, NIN, BVN) not justified by purpose. | F10: Form review worksheet | G10: Medium
A11: 7 | B11: Retention & disposal | C11: GAID Art. 49(3)-(4); NDPA s.24(1)(d) | D11: Retention periods defined; data disposed of securely (default not later than 6 months after purpose ends unless justified). | E11: Obtain retention schedule; inspect archives/systems for data past retention; review disposal records (shredding/wiping). | F11: Retention schedule; disposal certificates | G11: Medium
A12: 8 | B12: Accuracy & rectification | C12: GAID Art. 36; NDPA s.24(1)(e) | D12: Data subjects can verify and correct data; input errors by the unit corrected free of charge. | E12: Review rectification procedure (e.g., name/DOB corrections); sample 5 requests for timeliness and absence of fees for unit errors. | F12: Correction requests; procedure | G12: Medium
A13: 9 | B13: Data subject rights | C13: GAID Art. 36-38, 40; NDPA s.34-38 | D13: Access, erasure, portability, objection requests and SNAGs are logged, escalated to the DPO and resolved on time. | E13: Enquire about requests received by the unit; test log and escalation to DPO. | F13: Rights request log; SNAG responses | G13: Medium
A14: 10 | B14: Physical & access security | C14: NDPA s.39; GAID Art. 29 | D14: Physical records and system access are restricted on a need-to-know basis. | E14: Inspect records rooms/cabinets; review user access list for its systems and confirm leavers are removed. | F14: Access lists; site inspection photos | G14: High
A15: 11 | B15: Technical security & devices | C15: GAID Art. 10(5), 29(2); NDPA s.39 | D15: Unit devices and online systems use authentication, encryption, updated software and are audited frequently. | E15: Sample 5 unit laptops/desktops: password, screen lock, encryption, antivirus, OS updates; check use of personal email/USB for personal data. | F15: Device checklist; screenshots | G15: High
A16: 12 | B16: Third-party processors & DPAs | C16: GAID Art. 34; NDPA s.29 | D16: Vendors/partners processing personal data for {u} have Data Processing Agreements and were vetted. | E16: List third parties receiving data from the unit; inspect DPAs against Art. 34(2). | F16: Vendor list; DPAs | G16: High
... A26: 22 | B26: Prior findings follow-up | C26: GAID Art. 10(1), (11) | D26: Previous audit/CAR findings for the unit are remediated. | E26: Obtain prior-year findings for the unit; verify implementation of each agreed action. | F26: Prior report; action tracker | G26: Medium

Sheet Timeline
A1: Audit & CAR Filing Timeline — 2026 Audit Year
A3: Phase | B3: Activity | C3: Start | D3: End | E3: Days | F3: Owner | G3: GAID Reference | H3: Status
A4: 1. Planning | B4: Confirm DCMI level, engage licensed DPCO, approve audit plan & universe | C4: 46296 | D4: 46325 | E4: =NETWORKDAYS(C4,D4) -> 22 | F4: DPO / Internal Audit | G4: Art. 8, 9, 10(14) | H4: Not Started
A5: 1. Planning | B5: Issue ROPA & data inventory requests to all units | C5: 46307 | D5: 46325 | E5: =NETWORKDAYS(C5,D5) -> 15 | F5: DPO | G5: Art. 13 | H5: Not Started
A6: 2. Fieldwork | B6: Central governance (DPO office) | C6: 46328 | D6: 46339 | E6: =NETWORKDAYS(C6,D6) -> 10 | F6: Audit team | G6: Art. 10-14 | H6: Not Started
A7: 2. Fieldwork | B7: Directorates | C7: 46342 | D7: 46367 | E7: =NETWORKDAYS(C7,D7) -> 20 | F7: Audit team | G7: Art. 10(2)-(5) | H7: Not Started
A8: 2. Fieldwork | B8: Central administrative departments | C8: 46391 | D8: 46409 | E8: =NETWORKDAYS(C8,D8) -> 15 | F8: Audit team | G8: Art. 10(2)-(5) | H8: Not Started
A9: 2. Fieldwork | B9: Faculties | C9: 46412 | D9: 46430 | E9: =NETWORKDAYS(C9,D9) -> 15 | F9: Audit team | G9: Art. 10(2)-(5) | H9: Not Started
A10: 2. Fieldwork | B10: Schools | C10: 46433 | D10: 46444 | E10: =NETWORKDAYS(C10,D10) -> 10 | F10: Audit team | G10: Art. 10(2)-(5) | H10: Not Started
A11: 3. Reporting | B11: Draft unit reports & management responses | C11: 46447 | D11: 46456 | E11: =NETWORKDAYS(C11,D11) -> 8 | F11: Audit team / Unit heads | G11: Art. 10(1) | H11: Not Started
A12: 3. Reporting | B12: Consolidate findings into Schedule 2 CAR template; DPCO verification of SADPR & DPIAs | C12: 46457 | D12: 46465 | E12: =NETWORKDAYS(C12,D12) -> 7 | F12: DPCO / DPO | G12: Art. 10(6), 13(4), 28(5) | H12: Not Started
A13: 4. Filing | B13: Management approval & payment of CAR filing fee | C13: 46468 | D13: 46471 | E13: =NETWORKDAYS(C13,D13) -> 4 | F13: VC / Bursary | G13: Art. 10(10) & Sch. 10 | H13: Not Started
A14: 4. Filing | B14: File CAR on NDPC portal via DPCO (deadline 31 March) | C14: 46472 | D14: 46477 | E14: =NETWORKDAYS(C14,D14) -> 4 | F14: DPCO | G14: Art. 10(7), 10(12) | H14: Not Started
A15: 5. Follow-up | B15: Respond to NDPC requests; track remediation of findings | C15: 46478 | D15: 46568 | E15: =NETWORKDAYS(C15,D15) -> 65 | F15: DPO | G15: Art. 10(11), 10(13) | H15: Not Started
A17: Note: weekend days excluded via NETWORKDAYS; public holidays (Christmas, New Year, Easter) not deducted — adjust dates if needed.

Sheet CEN-DPO Office
A1: Compliance Audit Work Plan — Data Protection Office (DPO) & Central Governance | N1: ← Back to Dashboard
A2: NDPA 2023 / GAID 2025 — Article 10 Compliance Audit Returns (CAR) | Audit year 2026 | CAR due 31 March 2027
A4: Unit | C4: Data Protection Office (DPO) & Central Governance | H4: Lead Auditor | K4: [Enter name]
A5: Unit type | C5: Central Governance | H5: Planned Start | K5: 46328
A6: Reports to | C6: Vice-Chancellor / University Management | H6: Planned End | K6: 46339
A7: Head of Unit | C7: [Enter name] | H7: Controls in plan | K7: =COUNTA(A15:A53) -> 39
A8: Data subjects | C8: All data subjects of the University | H8: Completed | K8: =COUNTIF(K15:K53,"Completed") -> 0
A9: Key personal data | C9: Consolidated ROPA, DPIAs, breach register, complaints, CAR records | H9: Compliant | K9: =COUNTIF(L15:L53,"Compliant") -> 0
A10: Key systems / records | C10: CAR portal, ROPA register, breach log | H10: Partially Compliant | K10: =COUNTIF(L15:L53,"Partially Compliant") -> 0
A11: Inherent data risk | C11: High | H11: Non-Compliant | K11: =COUNTIF(L15:L53,"Non-Compliant") -> 0
H12: Not Applicable | K12: =COUNTIF(L15:L53,"Not Applicable") -> 0
H13: Compliance Score | K13: =_xlfn.IFERROR(AVERAGE(M15:M53),"")
A14: Ref | B14: CAR Area | C14: GAID / NDPA Reference | D14: Control Objective | E14: Audit Procedure | F14: Evidence to Obtain | G14: Risk | H14: Planned Start | I14: Planned End | J14: Auditor | K14: Status | L14: Compliance Rating | M14: Score | N14: Findings | O14: Recommendation | P14: Management Response / Owner | Q14: Target Date
A15: CEN-DO-01 | B15: Registration as DCMI | C15: GAID Art. 8, 9 & Sch. 7; NDPA s.44 | D15: University is registered with NDPC as a Data Controller of Major Importance at the correct level (UHL/EHL/OHL). | E15: Confirm NDPC registration certificate, check classification against Schedule 7 criteria (student + staff population, sensitivity) and confirm level is still accurate. | F15: NDPC registration certificate; classification working paper | G15: High | H15: =$K$5 -> 46328 | I15: =$K$6 -> 46339 | K15: Not Started | M15: =IF(L15="Compliant",1,IF(L15="Partially Compliant",0.5,IF(L15="Non-Compliant",0,"")))
A16: CEN-DO-02 | B16: Registration changes | C16: GAID Art. 9(4) | D16: Significant changes to registration details notified to NDPC within 60 days. | E16: Identify changes in the year (new VC/DPO, new campuses, new systems) and trace notification to NDPC within 60 days. | F16: Change log; NDPC correspondence | G16: Medium | H16: =$K$5 -> 46328 | I16: =$K$6 -> 46339 | K16: Not Started | M16: =IF(L16="Compliant",1,IF(L16="Partially Compliant",0.5,IF(L16="Non-Compliant",0,"")))
A17: CEN-DO-03 | B17: CAR filing | C17: GAID Art. 10(6),(7),(12),(14) | D17: Annual CAR prepared on the Schedule 2 template and filed through a licensed DPCO via the NDPC portal by 31 March. | E17: Confirm engagement of an NDPC-licensed DPCO, review prior-year CAR filing date and portal acknowledgement, confirm current CAR timetable meets 31 March deadline. | F17: DPCO licence; DPCO engagement letter; prior CAR acknowledgement / certificate | G17: High | H17: =$K$5 -> 46328 | I17: =$K$6 -> 46339 | K17: Not Started | M17: =IF(L17="Compliant",1,IF(L17="Partially Compliant",0.5,IF(L17="Non-Compliant",0,"")))
A18: CEN-DO-04 | B18: CAR fees & penalties | C18: GAID Art. 10(9),(10) & Sch. 10 | D18: Filing fee paid at the correct rate; no 50% late-filing penalty incurred. | E18: Recompute filing fee per Schedule 10, trace payment in Bursary records, check for late-filing penalty. | F18: Payment receipt; Schedule 10 computation | G18: Medium | H18: =$K$5 -> 46328 | I18: =$K$6 -> 46339 | K18: Not Started | M18: =IF(L18="Compliant",1,IF(L18="Partially Compliant",0.5,IF(L18="Non-Compliant",0,"")))
A19: CEN-DO-05 | B19: NDPC information requests | C19: GAID Art. 10(11) & (13) | D19: Additional information requested by NDPC after CAR filing was provided promptly; CAR certificate obtained. | E19: Review NDPC correspondence after last filing and confirm timely responses and receipt of CAR certificate. | F19: NDPC letters; response log; CAR certificate | G19: Medium | H19: =$K$5 -> 46328 | I19: =$K$6 -> 46339 | K19: Not Started | M19: =IF(L19="Compliant",1,IF(L19="Partially Compliant",0.5,IF(L19="Non-Compliant",0,"")))
A20: CEN-DO-06 | B20: DPO designation | C20: GAID Art. 11, 12; NDPA s.32 | D20: DPO formally designated, reports directly to management, is resourced and free from conflict of interest. | E20: Review appointment letter, organogram, DPO budget and other roles held; confirm DPO contact details published and communicated to NDPC. | F20: Appointment letter; organogram; website DPO contact page | G20: High | H20: =$K$5 -> 46328 | I20: =$K$6 -> 46339 | K20: Not Started | M20: =IF(L20="Compliant",1,IF(L20="Partially Compliant",0.5,IF(L20="Non-Compliant",0,"")))
A21: CEN-DO-07 | B21: DPO credentials | C21: GAID Art. 14 & Sch. 3 | D21: DPO is certified and maintains CPD for Annual Credential Assessment. | E21: Inspect DPO certification and CPD evidence against Schedule 3 metrics. | F21: Certificates; CPD log | G21: Medium | H21: =$K$5 -> 46328 | I21: =$K$6 -> 46339 | K21: Not Started | M21: =IF(L21="Compliant",1,IF(L21="Partially Compliant",0.5,IF(L21="Non-Compliant",0,"")))
A22: CEN-DO-08 | B22: Semi-Annual DP Report | C22: GAID Art. 13 | D22: SADPR compiled twice in the year, acknowledged by management and filed with ROPA. | E22: Obtain both SADPRs, confirm coverage of Art. 13(5)(a)-(m) items and management acknowledgement. | F22: SADPR (H1 & H2); acknowledgement | G22: High | H22: =$K$5 -> 46328 | I22: =$K$6 -> 46339 | K22: Not Started | M22: =IF(L22="Compliant",1,IF(L22="Partially Compliant",0.5,IF(L22="Non-Compliant",0,"")))
A23: CEN-DO-09 | B23: Consolidated ROPA | C23: GAID Art. 13(3); Art. 52 | D23: University-wide ROPA is complete and covers every faculty, school, directorate and department. | E23: Reconcile consolidated ROPA against the audit universe on the Dashboard; list units without ROPA entries. | F23: Consolidated ROPA; reconciliation | G23: High | H23: =$K$5 -> 46328 | I23: =$K$6 -> 46339 | K23: Not Started | M23: =IF(L23="Compliant",1,IF(L23="Partially Compliant",0.5,IF(L23="Non-Compliant",0,"")))
A24: CEN-DO-10 | B24: Compliance schedules | C24: GAID Art. 7(d),(h) | D24: Schedule of NDPA obligations and compliance timelines exists and is tracked. | E24: Review compliance schedule and test status of five obligations to evidence. | F24: Compliance schedule / tracker | G24: Medium | H24: =$K$5 -> 46328 | I24: =$K$6 -> 46339 | K24: Not Started | M24: =IF(L24="Compliant",1,IF(L24="Partially Compliant",0.5,IF(L24="Non-Compliant",0,"")))
A25: CEN-DO-11 | B25: MEM schedule | C25: GAID Art. 29(1)-(4) | D25: Monitoring, Evaluation & Maintenance schedule for data security exists and is vetted by a certified information security officer. | E25: Inspect MEM schedule; confirm people/process/technology coverage and certification sign-off. | F25: MEM schedule; InfoSec officer certificate | G25: High | H25: =$K$5 -> 46328 | I25: =$K$6 -> 46339 | K25: Not Started | M25: =IF(L25="Compliant",1,IF(L25="Partially Compliant",0.5,IF(L25="Non-Compliant",0,"")))
A26: CEN-DO-12 | B26: SToP schedule | C26: GAID Art. 30(1)-(5); Art. 46 | D26: University-wide Sensitisation & Training on Privacy schedule is approved and published to staff. | E26: Inspect SToP schedule, publication medium, and evaluation of stop/start/continue practices. | F26: SToP schedule; intranet/notice board evidence | G26: Medium | H26: =$K$5 -> 46328 | I26: =$K$6 -> 46339 | K26: Not Started | M26: =IF(L26="Compliant",1,IF(L26="Partially Compliant",0.5,IF(L26="Non-Compliant",0,"")))
... A53: CEN-DO-39 | B53: Prior findings follow-up | C53: GAID Art. 10(1), (11) | D53: Previous audit/CAR findings for the unit are remediated. | E53: Obtain prior-year findings for Data Protection Office (DPO) & Central Governance; verify implementation of each agreed action. | F53: Prior report; action tracker | G53: High | H53: =$K$5 -> 46328 | I53: =$K$6 -> 46339 | K53: Not Started | M53: =IF(L53="Compliant",1,IF(L53="Partially Compliant",0.5,IF(L53="Non-Compliant",0,"")))
A55: Bold teal CAR Areas = controls specific to this unit. Base controls are listed on the 'CAR Framework' tab.

Sheet DIR-ICT
A1: Compliance Audit Work Plan — Directorate of Information & Communication Technology (DICT) | N1: ← Back to Dashboard
A2: NDPA 2023 / GAID 2025 — Article 10 Compliance Audit Returns (CAR) | Audit year 2026 | CAR due 31 March 2027
A4: Unit | C4: Directorate of Information & Communication Technology (DICT) | H4: Lead Auditor | K4: [Enter name]
A5: Unit type | C5: Directorate | H5: Planned Start | K5: 46342
A6: Reports to | C6: Vice-Chancellor | H6: Planned End | K6: 46367
A7: Head of Unit | C7: [Enter name] | H7: Controls in plan | K7: =COUNTA(A15:A42) -> 28
A8: Data subjects | C8: Students, applicants, staff, alumni, website visitors | H8: Completed | K8: =COUNTIF(K15:K42,"Completed") -> 0
A9: Key personal data | C9: Portal credentials, biodata, results, email, logs, biometrics | H9: Compliant | K9: =COUNTIF(L15:L42,"Compliant") -> 0
A10: Key systems / records | C10: Student portal, ERP/SIS, email, LMS hosting, data centre, cloud services | H10: Partially Compliant | K10: =COUNTIF(L15:L42,"Partially Compliant") -> 0
A11: Inherent data risk | C11: High | H11: Non-Compliant | K11: =COUNTIF(L15:L42,"Non-Compliant") -> 0
H12: Not Applicable | K12: =COUNTIF(L15:L42,"Not Applicable") -> 0
H13: Compliance Score | K13: =_xlfn.IFERROR(AVERAGE(M15:M42),"")
A14: Ref | B14: CAR Area | C14: GAID / NDPA Reference | D14: Control Objective | E14: Audit Procedure | F14: Evidence to Obtain | G14: Risk | H14: Planned Start | I14: Planned End | J14: Auditor | K14: Status | L14: Compliance Rating | M14: Score | N14: Findings | O14: Recommendation | P14: Management Response / Owner | Q14: Target Date
A15: DIR-ICT-01 | B15: ROPA | C15: GAID Art. 13(2)-(3), Art. 52; NDPA s.24(3) | D15: All processing activities of the unit are captured in the Record of Processing Activities (ROPA) submitted to the DPO. | E15: Walk through Directorate of Information & Communication Technology (DICT)'s key processing (portal administration, account management, hosting and backups) and confirm each activity is captured in the ROPA with purpose, data categories, recipients and retention. | F15: Unit ROPA extract; process walkthrough notes | G15: High | H15: =$K$5 -> 46342 | I15: =$K$6 -> 46367 | K15: Not Started | M15: =IF(L15="Compliant",1,IF(L15="Partially Compliant",0.5,IF(L15="Non-Compliant",0,"")))
A16: DIR-ICT-02 | B16: Data inventory & sensitive data | C16: NDPA s.30; GAID Art. 28(3)(d) | D16: Personal and sensitive personal data held by the unit is identified and classified. | E16: Inventory data held (Portal credentials, biodata, results, email, logs, biometrics); flag sensitive categories and confirm they are recorded as such. | F16: Data inventory; classification register | G16: High | H16: =$K$5 -> 46342 | I16: =$K$6 -> 46367 | K16: Not Started | M16: =IF(L16="Compliant",1,IF(L16="Partially Compliant",0.5,IF(L16="Non-Compliant",0,"")))
A17: DIR-ICT-03 | B17: Lawful basis | C17: GAID Art. 16, 23; NDPA s.25 | D17: A documented lawful basis exists for each processing activity; legitimate interest supported by LIA. | E17: For each ROPA activity, confirm lawful basis is recorded and appropriate; where legitimate interest is used, inspect Schedule 8 LIA. | F17: Lawful basis register; LIAs | G17: High | H17: =$K$5 -> 46342 | I17: =$K$6 -> 46367 | K17: Not Started | M17: =IF(L17="Compliant",1,IF(L17="Partially Compliant",0.5,IF(L17="Non-Compliant",0,"")))
A18: DIR-ICT-04 | B18: Consent (CAR disclosure) | C18: GAID Art. 17, 18(1)-(2); NDPA s.26 | D18: Consent is obtained and recorded where required (marketing, sensitive data, children, incompatible further processing, transfers, automated decisions) — CAR must state reliance. | E18: Identify Art. 18(1) activities in Directorate of Information & Communication Technology (DICT); test consent capture, records and ease of withdrawal for a sample of 5. | F18: Consent forms/records; withdrawal mechanism | G18: High | H18: =$K$5 -> 46342 | I18: =$K$6 -> 46367 | K18: Not Started | M18: =IF(L18="Compliant",1,IF(L18="Partially Compliant",0.5,IF(L18="Non-Compliant",0,"")))
A19: DIR-ICT-05 | B19: Privacy notice at collection | C19: GAID Art. 27; Art. 7(j)-(m); NDPA s.27 | D19: Data subjects receive clear privacy information at every collection point (forms, portals, surveys). | E19: Collect all forms/portals used by Directorate of Information & Communication Technology (DICT); check each notice against Art. 27(3)(a)-(j). | F19: Forms; screenshots; notice checklist | G19: High | H19: =$K$5 -> 46342 | I19: =$K$6 -> 46367 | K19: Not Started | M19: =IF(L19="Compliant",1,IF(L19="Partially Compliant",0.5,IF(L19="Non-Compliant",0,"")))
A20: DIR-ICT-06 | B20: Minimisation & purpose limitation | C20: GAID Art. 15 & Sch. 1; NDPA s.24(1)(b),(c) | D20: Only data necessary for the stated purpose is collected and used. | E20: Review fields on Directorate of Information & Communication Technology (DICT) forms and systems (Student portal, ERP/SIS, email, LMS hosting, data centre, cloud services); identify excessive fields (e.g., religion, NIN, BVN) not justified by purpose. | F20: Form review worksheet | G20: High | H20: =$K$5 -> 46342 | I20: =$K$6 -> 46367 | K20: Not Started | M20: =IF(L20="Compliant",1,IF(L20="Partially Compliant",0.5,IF(L20="Non-Compliant",0,"")))
A21: DIR-ICT-07 | B21: Retention & disposal | C21: GAID Art. 49(3)-(4); NDPA s.24(1)(d) | D21: Retention periods defined; data disposed of securely (default not later than 6 months after purpose ends unless justified). | E21: Obtain retention schedule; inspect archives/systems for data past retention; review disposal records (shredding/wiping). | F21: Retention schedule; disposal certificates | G21: High | H21: =$K$5 -> 46342 | I21: =$K$6 -> 46367 | K21: Not Started | M21: =IF(L21="Compliant",1,IF(L21="Partially Compliant",0.5,IF(L21="Non-Compliant",0,"")))
A22: DIR-ICT-08 | B22: Accuracy & rectification | C22: GAID Art. 36; NDPA s.24(1)(e) | D22: Data subjects can verify and correct data; input errors by the unit corrected free of charge. | E22: Review rectification procedure (e.g., name/DOB corrections); sample 5 requests for timeliness and absence of fees for unit errors. | F22: Correction requests; procedure | G22: High | H22: =$K$5 -> 46342 | I22: =$K$6 -> 46367 | K22: Not Started | M22: =IF(L22="Compliant",1,IF(L22="Partially Compliant",0.5,IF(L22="Non-Compliant",0,"")))
A23: DIR-ICT-09 | B23: Data subject rights | C23: GAID Art. 36-38, 40; NDPA s.34-38 | D23: Access, erasure, portability, objection requests and SNAGs are logged, escalated to the DPO and resolved on time. | E23: Enquire about requests received by Directorate of Information & Communication Technology (DICT); test log and escalation to DPO. | F23: Rights request log; SNAG responses | G23: High | H23: =$K$5 -> 46342 | I23: =$K$6 -> 46367 | K23: Not Started | M23: =IF(L23="Compliant",1,IF(L23="Partially Compliant",0.5,IF(L23="Non-Compliant",0,"")))
A24: DIR-ICT-10 | B24: Physical & access security | C24: NDPA s.39; GAID Art. 29 | D24: Physical records and system access are restricted on a need-to-know basis. | E24: Inspect records rooms/cabinets; review user access list for Student portal, ERP/SIS, email, LMS hosting, data centre, cloud services and confirm leavers are removed. | F24: Access lists; site inspection photos | G24: High | H24: =$K$5 -> 46342 | I24: =$K$6 -> 46367 | K24: Not Started | M24: =IF(L24="Compliant",1,IF(L24="Partially Compliant",0.5,IF(L24="Non-Compliant",0,"")))
A25: DIR-ICT-11 | B25: Technical security & devices | C25: GAID Art. 10(5), 29(2); NDPA s.39 | D25: Unit devices and online systems use authentication, encryption, updated software and are audited frequently. | E25: Sample 5 unit laptops/desktops: password, screen lock, encryption, antivirus, OS updates; check use of personal email/USB for personal data. | F25: Device checklist; screenshots | G25: High | H25: =$K$5 -> 46342 | I25: =$K$6 -> 46367 | K25: Not Started | M25: =IF(L25="Compliant",1,IF(L25="Partially Compliant",0.5,IF(L25="Non-Compliant",0,"")))
A26: DIR-ICT-12 | B26: Third-party processors & DPAs | C26: GAID Art. 34; NDPA s.29 | D26: Vendors/partners processing personal data for Directorate of Information & Communication Technology (DICT) have Data Processing Agreements and were vetted. | E26: List third parties receiving data from Directorate of Information & Communication Technology (DICT); inspect DPAs against Art. 34(2). | F26: Vendor list; DPAs | G26: High | H26: =$K$5 -> 46342 | I26: =$K$6 -> 46367 | K26: Not Started | M26: =IF(L26="Compliant",1,IF(L26="Partially Compliant",0.5,IF(L26="Non-Compliant",0,"")))
... A42: DIR-ICT-28 | B42: Software deployment | C42: GAID Art. 31 | D42: University apps/portals interacting with data subjects had DPIA, privacy by design and in-app privacy statement. | E42: For each app launched/updated in the year, inspect DPIA and pre-installation privacy statement per Art. 31(2)(e). | F42: App DPIAs; screenshots | G42: High | H42: =$K$5 -> 46342 | I42: =$K$6 -> 46367 | K42: Not Started | M42: =IF(L42="Compliant",1,IF(L42="Partially Compliant",0.5,IF(L42="Non-Compliant",0,"")))
A44: Bold teal CAR Areas = controls specific to this unit. Base controls are listed on the 'CAR Framework' tab.

Sheet DIR-Academic Planning
A1: Compliance Audit Work Plan — Directorate of Academic Planning | N1: ← Back to Dashboard
A2: NDPA 2023 / GAID 2025 — Article 10 Compliance Audit Returns (CAR) | Audit year 2026 | CAR due 31 March 2027
A4: Unit | C4: Directorate of Academic Planning | H4: Lead Auditor | K4: [Enter name]
A5: Unit type | C5: Directorate | H5: Planned Start | K5: 46342
A6: Reports to | C6: Vice-Chancellor | H6: Planned End | K6: 46367
A7: Head of Unit | C7: [Enter name] | H7: Controls in plan | K7: =COUNTA(A15:A38) -> 24
A8: Data subjects | C8: Students, staff | H8: Completed | K8: =COUNTIF(K15:K38,"Completed") -> 0
A9: Key personal data | C9: Enrolment statistics, staff nominal roll, NUC returns | H9: Compliant | K9: =COUNTIF(L15:L38,"Compliant") -> 0
A10: Key systems / records | C10: NUC portal, planning databases, spreadsheets | H10: Partially Compliant | K10: =COUNTIF(L15:L38,"Partially Compliant") -> 0
A11: Inherent data risk | C11: Medium | H11: Non-Compliant | K11: =COUNTIF(L15:L38,"Non-Compliant") -> 0
H12: Not Applicable | K12: =COUNTIF(L15:L38,"Not Applicable") -> 0
H13: Compliance Score | K13: =_xlfn.IFERROR(AVERAGE(M15:M38),"")
A14: Ref | B14: CAR Area | C14: GAID / NDPA Reference | D14: Control Objective | E14: Audit Procedure | F14: Evidence to Obtain | G14: Risk | H14: Planned Start | I14: Planned End | J14: Auditor | K14: Status | L14: Compliance Rating | M14: Score | N14: Findings | O14: Recommendation | P14: Management Response / Owner | Q14: Target Date
A15: DIR-AP-01 | B15: ROPA | C15: GAID Art. 13(2)-(3), Art. 52; NDPA s.24(3) | D15: All processing activities of the unit are captured in the Record of Processing Activities (ROPA) submitted to the DPO. | E15: Walk through Directorate of Academic Planning's key processing (NUC/TETFund statistical returns, programme planning) and confirm each activity is captured in the ROPA with purpose, data categories, recipients and retention. | F15: Unit ROPA extract; process walkthrough notes | G15: High | H15: =$K$5 -> 46342 | I15: =$K$6 -> 46367 | K15: Not Started | M15: =IF(L15="Compliant",1,IF(L15="Partially Compliant",0.5,IF(L15="Non-Compliant",0,"")))
A16: DIR-AP-02 | B16: Data inventory & sensitive data | C16: NDPA s.30; GAID Art. 28(3)(d) | D16: Personal and sensitive personal data held by the unit is identified and classified. | E16: Inventory data held (Enrolment statistics, staff nominal roll, NUC returns); flag sensitive categories and confirm they are recorded as such. | F16: Data inventory; classification register | G16: High | H16: =$K$5 -> 46342 | I16: =$K$6 -> 46367 | K16: Not Started | M16: =IF(L16="Compliant",1,IF(L16="Partially Compliant",0.5,IF(L16="Non-Compliant",0,"")))
A17: DIR-AP-03 | B17: Lawful basis | C17: GAID Art. 16, 23; NDPA s.25 | D17: A documented lawful basis exists for each processing activity; legitimate interest supported by LIA. | E17: For each ROPA activity, confirm lawful basis is recorded and appropriate; where legitimate interest is used, inspect Schedule 8 LIA. | F17: Lawful basis register; LIAs | G17: High | H17: =$K$5 -> 46342 | I17: =$K$6 -> 46367 | K17: Not Started | M17: =IF(L17="Compliant",1,IF(L17="Partially Compliant",0.5,IF(L17="Non-Compliant",0,"")))
A18: DIR-AP-04 | B18: Consent (CAR disclosure) | C18: GAID Art. 17, 18(1)-(2); NDPA s.26 | D18: Consent is obtained and recorded where required (marketing, sensitive data, children, incompatible further processing, transfers, automated decisions) — CAR must state reliance. | E18: Identify Art. 18(1) activities in Directorate of Academic Planning; test consent capture, records and ease of withdrawal for a sample of 5. | F18: Consent forms/records; withdrawal mechanism | G18: High | H18: =$K$5 -> 46342 | I18: =$K$6 -> 46367 | K18: Not Started | M18: =IF(L18="Compliant",1,IF(L18="Partially Compliant",0.5,IF(L18="Non-Compliant",0,"")))
A19: DIR-AP-05 | B19: Privacy notice at collection | C19: GAID Art. 27; Art. 7(j)-(m); NDPA s.27 | D19: Data subjects receive clear privacy information at every collection point (forms, portals, surveys). | E19: Collect all forms/portals used by Directorate of Academic Planning; check each notice against Art. 27(3)(a)-(j). | F19: Forms; screenshots; notice checklist | G19: Medium | H19: =$K$5 -> 46342 | I19: =$K$6 -> 46367 | K19: Not Started | M19: =IF(L19="Compliant",1,IF(L19="Partially Compliant",0.5,IF(L19="Non-Compliant",0,"")))
A20: DIR-AP-06 | B20: Minimisation & purpose limitation | C20: GAID Art. 15 & Sch. 1; NDPA s.24(1)(b),(c) | D20: Only data necessary for the stated purpose is collected and used. | E20: Review fields on Directorate of Academic Planning forms and systems (NUC portal, planning databases, spreadsheets); identify excessive fields (e.g., religion, NIN, BVN) not justified by purpose. | F20: Form review worksheet | G20: Medium | H20: =$K$5 -> 46342 | I20: =$K$6 -> 46367 | K20: Not Started | M20: =IF(L20="Compliant",1,IF(L20="Partially Compliant",0.5,IF(L20="Non-Compliant",0,"")))
A21: DIR-AP-07 | B21: Retention & disposal | C21: GAID Art. 49(3)-(4); NDPA s.24(1)(d) | D21: Retention periods defined; data disposed of securely (default not later than 6 months after purpose ends unless justified). | E21: Obtain retention schedule; inspect archives/systems for data past retention; review disposal records (shredding/wiping). | F21: Retention schedule; disposal certificates | G21: Medium | H21: =$K$5 -> 46342 | I21: =$K$6 -> 46367 | K21: Not Started | M21: =IF(L21="Compliant",1,IF(L21="Partially Compliant",0.5,IF(L21="Non-Compliant",0,"")))
A22: DIR-AP-08 | B22: Accuracy & rectification | C22: GAID Art. 36; NDPA s.24(1)(e) | D22: Data subjects can verify and correct data; input errors by the unit corrected free of charge. | E22: Review rectification procedure (e.g., name/DOB corrections); sample 5 requests for timeliness and absence of fees for unit errors. | F22: Correction requests; procedure | G22: Medium | H22: =$K$5 -> 46342 | I22: =$K$6 -> 46367 | K22: Not Started | M22: =IF(L22="Compliant",1,IF(L22="Partially Compliant",0.5,IF(L22="Non-Compliant",0,"")))
A23: DIR-AP-09 | B23: Data subject rights | C23: GAID Art. 36-38, 40; NDPA s.34-38 | D23: Access, erasure, portability, objection requests and SNAGs are logged, escalated to the DPO and resolved on time. | E23: Enquire about requests received by Directorate of Academic Planning; test log and escalation to DPO. | F23: Rights request log; SNAG responses | G23: Medium | H23: =$K$5 -> 46342 | I23: =$K$6 -> 46367 | K23: Not Started | M23: =IF(L23="Compliant",1,IF(L23="Partially Compliant",0.5,IF(L23="Non-Compliant",0,"")))
A24: DIR-AP-10 | B24: Physical & access security | C24: NDPA s.39; GAID Art. 29 | D24: Physical records and system access are restricted on a need-to-know basis. | E24: Inspect records rooms/cabinets; review user access list for NUC portal, planning databases, spreadsheets and confirm leavers are removed. | F24: Access lists; site inspection photos | G24: High | H24: =$K$5 -> 46342 | I24: =$K$6 -> 46367 | K24: Not Started | M24: =IF(L24="Compliant",1,IF(L24="Partially Compliant",0.5,IF(L24="Non-Compliant",0,"")))
A25: DIR-AP-11 | B25: Technical security & devices | C25: GAID Art. 10(5), 29(2); NDPA s.39 | D25: Unit devices and online systems use authentication, encryption, updated software and are audited frequently. | E25: Sample 5 unit laptops/desktops: password, screen lock, encryption, antivirus, OS updates; check use of personal email/USB for personal data. | F25: Device checklist; screenshots | G25: High | H25: =$K$5 -> 46342 | I25: =$K$6 -> 46367 | K25: Not Started | M25: =IF(L25="Compliant",1,IF(L25="Partially Compliant",0.5,IF(L25="Non-Compliant",0,"")))
A26: DIR-AP-12 | B26: Third-party processors & DPAs | C26: GAID Art. 34; NDPA s.29 | D26: Vendors/partners processing personal data for Directorate of Academic Planning have Data Processing Agreements and were vetted. | E26: List third parties receiving data from Directorate of Academic Planning; inspect DPAs against Art. 34(2). | F26: Vendor list; DPAs | G26: High | H26: =$K$5 -> 46342 | I26: =$K$6 -> 46367 | K26: Not Started | M26: =IF(L26="Compliant",1,IF(L26="Partially Compliant",0.5,IF(L26="Non-Compliant",0,"")))
... A38: DIR-AP-24 | B38: Legal obligation reliance | C38: GAID Art. 22 | D38: Disclosures to regulators rest on a documented legal obligation limited to the minimum required. | E38: Review requests from NUC/JAMB/TETFund; confirm DPO opinion or legal basis on file. | F38: Request letters; DPO opinion | G38: Medium | H38: =$K$5 -> 46342 | I38: =$K$6 -> 46367 | K38: Not Started | M38: =IF(L38="Compliant",1,IF(L38="Partially Compliant",0.5,IF(L38="Non-Compliant",0,"")))
A40: Bold teal CAR Areas = controls specific to this unit. Base controls are listed on the 'CAR Framework' tab.

Sheet DIR-Quality Assurance
A1: Compliance Audit Work Plan — Directorate of Quality Assurance | N1: ← Back to Dashboard
A2: NDPA 2023 / GAID 2025 — Article 10 Compliance Audit Returns (CAR) | Audit year 2026 | CAR due 31 March 2027
A4: Unit | C4: Directorate of Quality Assurance | H4: Lead Auditor | K4: [Enter name]
A5: Unit type | C5: Directorate | H5: Planned Start | K5: 46342
A6: Reports to | C6: Vice-Chancellor | H6: Planned End | K6: 46367
A7: Head of Unit | C7: [Enter name] | H7: Controls in plan | K7: =COUNTA(A15:A38) -> 24
A8: Data subjects | C8: Students, lecturers | H8: Completed | K8: =COUNTIF(K15:K38,"Completed") -> 0
A9: Key personal data | C9: Course evaluation responses, staff appraisal inputs, accreditation files | H9: Compliant | K9: =COUNTIF(L15:L38,"Compliant") -> 0
A10: Key systems / records | C10: Survey tools (online forms), accreditation portal | H10: Partially Compliant | K10: =COUNTIF(L15:L38,"Partially Compliant") -> 0
A11: Inherent data risk | C11: Medium | H11: Non-Compliant | K11: =COUNTIF(L15:L38,"Non-Compliant") -> 0
H12: Not Applicable | K12: =COUNTIF(L15:L38,"Not Applicable") -> 0
H13: Compliance Score | K13: =_xlfn.IFERROR(AVERAGE(M15:M38),"")
A14: Ref | B14: CAR Area | C14: GAID / NDPA Reference | D14: Control Objective | E14: Audit Procedure | F14: Evidence to Obtain | G14: Risk | H14: Planned Start | I14: Planned End | J14: Auditor | K14: Status | L14: Compliance Rating | M14: Score | N14: Findings | O14: Recommendation | P14: Management Response / Owner | Q14: Target Date
A15: DIR-QA-01 | B15: ROPA | C15: GAID Art. 13(2)-(3), Art. 52; NDPA s.24(3) | D15: All processing activities of the unit are captured in the Record of Processing Activities (ROPA) submitted to the DPO. | E15: Walk through Directorate of Quality Assurance's key processing (student evaluation of teaching, accreditation preparation) and confirm each activity is captured in the ROPA with purpose, data categories, recipients and retention. | F15: Unit ROPA extract; process walkthrough notes | G15: High | H15: =$K$5 -> 46342 | I15: =$K$6 -> 46367 | K15: Not Started | M15: =IF(L15="Compliant",1,IF(L15="Partially Compliant",0.5,IF(L15="Non-Compliant",0,"")))
A16: DIR-QA-02 | B16: Data inventory & sensitive data | C16: NDPA s.30; GAID Art. 28(3)(d) | D16: Personal and sensitive personal data held by the unit is identified and classified. | E16: Inventory data held (Course evaluation responses, staff appraisal inputs, accreditation files); flag sensitive categories and confirm they are recorded as such. | F16: Data inventory; classification register | G16: High | H16: =$K$5 -> 46342 | I16: =$K$6 -> 46367 | K16: Not Started | M16: =IF(L16="Compliant",1,IF(L16="Partially Compliant",0.5,IF(L16="Non-Compliant",0,"")))
A17: DIR-QA-03 | B17: Lawful basis | C17: GAID Art. 16, 23; NDPA s.25 | D17: A documented lawful basis exists for each processing activity; legitimate interest supported by LIA. | E17: For each ROPA activity, confirm lawful basis is recorded and appropriate; where legitimate interest is used, inspect Schedule 8 LIA. | F17: Lawful basis register; LIAs | G17: High | H17: =$K$5 -> 46342 | I17: =$K$6 -> 46367 | K17: Not Started | M17: =IF(L17="Compliant",1,IF(L17="Partially Compliant",0.5,IF(L17="Non-Compliant",0,"")))
A18: DIR-QA-04 | B18: Consent (CAR disclosure) | C18: GAID Art. 17, 18(1)-(2); NDPA s.26 | D18: Consent is obtained and recorded where required (marketing, sensitive data, children, incompatible further processing, transfers, automated decisions) — CAR must state reliance. | E18: Identify Art. 18(1) activities in Directorate of Quality Assurance; test consent capture, records and ease of withdrawal for a sample of 5. | F18: Consent forms/records; withdrawal mechanism | G18: High | H18: =$K$5 -> 46342 | I18: =$K$6 -> 46367 | K18: Not Started | M18: =IF(L18="Compliant",1,IF(L18="Partially Compliant",0.5,IF(L18="Non-Compliant",0,"")))
A19: DIR-QA-05 | B19: Privacy notice at collection | C19: GAID Art. 27; Art. 7(j)-(m); NDPA s.27 | D19: Data subjects receive clear privacy information at every collection point (forms, portals, surveys). | E19: Collect all forms/portals used by Directorate of Quality Assurance; check each notice against Art. 27(3)(a)-(j). | F19: Forms; screenshots; notice checklist | G19: Medium | H19: =$K$5 -> 46342 | I19: =$K$6 -> 46367 | K19: Not Started | M19: =IF(L19="Compliant",1,IF(L19="Partially Compliant",0.5,IF(L19="Non-Compliant",0,"")))
A20: DIR-QA-06 | B20: Minimisation & purpose limitation | C20: GAID Art. 15 & Sch. 1; NDPA s.24(1)(b),(c) | D20: Only data necessary for the stated purpose is collected and used. | E20: Review fields on Directorate of Quality Assurance forms and systems (Survey tools (online forms), accreditation portal); identify excessive fields (e.g., religion, NIN, BVN) not justified by purpose. | F20: Form review worksheet | G20: Medium | H20: =$K$5 -> 46342 | I20: =$K$6 -> 46367 | K20: Not Started | M20: =IF(L20="Compliant",1,IF(L20="Partially Compliant",0.5,IF(L20="Non-Compliant",0,"")))
A21: DIR-QA-07 | B21: Retention & disposal | C21: GAID Art. 49(3)-(4); NDPA s.24(1)(d) | D21: Retention periods defined; data disposed of securely (default not later than 6 months after purpose ends unless justified). | E21: Obtain retention schedule; inspect archives/systems for data past retention; review disposal records (shredding/wiping). | F21: Retention schedule; disposal certificates | G21: Medium | H21: =$K$5 -> 46342 | I21: =$K$6 -> 46367 | K21: Not Started | M21: =IF(L21="Compliant",1,IF(L21="Partially Compliant",0.5,IF(L21="Non-Compliant",0,"")))
A22: DIR-QA-08 | B22: Accuracy & rectification | C22: GAID Art. 36; NDPA s.24(1)(e) | D22: Data subjects can verify and correct data; input errors by the unit corrected free of charge. | E22: Review rectification procedure (e.g., name/DOB corrections); sample 5 requests for timeliness and absence of fees for unit errors. | F22: Correction requests; procedure | G22: Medium | H22: =$K$5 -> 46342 | I22: =$K$6 -> 46367 | K22: Not Started | M22: =IF(L22="Compliant",1,IF(L22="Partially Compliant",0.5,IF(L22="Non-Compliant",0,"")))
A23: DIR-QA-09 | B23: Data subject rights | C23: GAID Art. 36-38, 40; NDPA s.34-38 | D23: Access, erasure, portability, objection requests and SNAGs are logged, escalated to the DPO and resolved on time. | E23: Enquire about requests received by Directorate of Quality Assurance; test log and escalation to DPO. | F23: Rights request log; SNAG responses | G23: Medium | H23: =$K$5 -> 46342 | I23: =$K$6 -> 46367 | K23: Not Started | M23: =IF(L23="Compliant",1,IF(L23="Partially Compliant",0.5,IF(L23="Non-Compliant",0,"")))
A24: DIR-QA-10 | B24: Physical & access security | C24: NDPA s.39; GAID Art. 29 | D24: Physical records and system access are restricted on a need-to-know basis. | E24: Inspect records rooms/cabinets; review user access list for Survey tools (online forms), accreditation portal and confirm leavers are removed. | F24: Access lists; site inspection photos | G24: High | H24: =$K$5 -> 46342 | I24: =$K$6 -> 46367 | K24: Not Started | M24: =IF(L24="Compliant",1,IF(L24="Partially Compliant",0.5,IF(L24="Non-Compliant",0,"")))
A25: DIR-QA-11 | B25: Technical security & devices | C25: GAID Art. 10(5), 29(2); NDPA s.39 | D25: Unit devices and online systems use authentication, encryption, updated software and are audited frequently. | E25: Sample 5 unit laptops/desktops: password, screen lock, encryption, antivirus, OS updates; check use of personal email/USB for personal data. | F25: Device checklist; screenshots | G25: High | H25: =$K$5 -> 46342 | I25: =$K$6 -> 46367 | K25: Not Started | M25: =IF(L25="Compliant",1,IF(L25="Partially Compliant",0.5,IF(L25="Non-Compliant",0,"")))
A26: DIR-QA-12 | B26: Third-party processors & DPAs | C26: GAID Art. 34; NDPA s.29 | D26: Vendors/partners processing personal data for Directorate of Quality Assurance have Data Processing Agreements and were vetted. | E26: List third parties receiving data from Directorate of Quality Assurance; inspect DPAs against Art. 34(2). | F26: Vendor list; DPAs | G26: High | H26: =$K$5 -> 46342 | I26: =$K$6 -> 46367 | K26: Not Started | M26: =IF(L26="Compliant",1,IF(L26="Partially Compliant",0.5,IF(L26="Non-Compliant",0,"")))
... A38: DIR-QA-24 | B38: Use of evaluations | C38: GAID Art. 41, 42(5) | D38: Evaluation results used against staff are fair, accurate and not solely automated. | E38: Review how evaluation scores feed appraisal/promotion; confirm human review. | F38: QA procedure; appraisal guidelines | G38: Medium | H38: =$K$5 -> 46342 | I38: =$K$6 -> 46367 | K38: Not Started | M38: =IF(L38="Compliant",1,IF(L38="Partially Compliant",0.5,IF(L38="Non-Compliant",0,"")))
A40: Bold teal CAR Areas = controls specific to this unit. Base controls are listed on the 'CAR Framework' tab.

Sheet DIR-Physical Planning
